Workbook

Sheet 活動計画書
G1: ="令和"&J9-2018&"年" -> 令和7年 | H1: 月 日
E3: ="令和"&J9-2018&"年 "&J10&"月" -> 令和7年 4月 | F3: 活動計画書 | G3: 電子計算機部
E5: (学生) | G5: (顧問)
A6: 日付 | B6: 曜日 | C6: 活動時間 | F6: 活動場所 | G6: 活動予定 | H6: 担当教員
A7: 1 | B7: ="("&TEXT(DATE($J$9,$J$10,A7),"aaa")&")" -> (火) | C7: 0.625 | D7: － | E7: 0.70833333
A8: 2 | B8: ="("&TEXT(DATE($J$9,$J$10,A8),"aaa")&")" -> (水) | D8: － | J8: 活動年月
A9: 3 | B9: ="("&TEXT(DATE($J$9,$J$10,A9),"aaa")&")" -> (木) | D9: － | J9: 2025 | K9: 年
A10: 4 | B10: ="("&TEXT(DATE($J$9,$J$10,A10),"aaa")&")" -> (金) | D10: － | J10: 4 | K10: 月
A11: 5 | B11: ="("&TEXT(DATE($J$9,$J$10,A11),"aaa")&")" -> (土) | D11: －
A12: 6 | B12: ="("&TEXT(DATE($J$9,$J$10,A12),"aaa")&")" -> (日) | D12: － | J12: クラブ名
A13: 7 | B13: ="("&TEXT(DATE($J$9,$J$10,A13),"aaa")&")" -> (月) | D13: － | J13: 硬式野球部
A14: 8 | B14: ="("&TEXT(DATE($J$9,$J$10,A14),"aaa")&")" -> (火) | D14: － | J14: ソフトテニス部
A15: 9 | B15: ="("&TEXT(DATE($J$9,$J$10,A15),"aaa")&")" -> (水) | D15: － | J15: 陸上競技部
A16: 10 | B16: ="("&TEXT(DATE($J$9,$J$10,A16),"aaa")&")" -> (木) | D16: － | J16: バレーボール部
A17: 11 | B17: ="("&TEXT(DATE($J$9,$J$10,A17),"aaa")&")" -> (金) | D17: － | J17: バスケットボール部
A18: 12 | B18: ="("&TEXT(DATE($J$9,$J$10,A18),"aaa")&")" -> (土) | D18: － | J18: サッカー部
A19: 13 | B19: ="("&TEXT(DATE($J$9,$J$10,A19),"aaa")&")" -> (日) | D19: － | J19: 卓球部
A20: 14 | B20: ="("&TEXT(DATE($J$9,$J$10,A20),"aaa")&")" -> (月) | D20: － | J20: 柔道部
A21: 15 | B21: ="("&TEXT(DATE($J$9,$J$10,A21),"aaa")&")" -> (火) | D21: － | J21: 剣道部
A22: 16 | B22: ="("&TEXT(DATE($J$9,$J$10,A22),"aaa")&")" -> (水) | D22: － | J22: ハンドボール部
A23: 17 | B23: ="("&TEXT(DATE($J$9,$J$10,A23),"aaa")&")" -> (木) | D23: － | J23: テニス部
... A26: 20 | B26: ="("&TEXT(DATE($J$9,$J$10,A26),"aaa")&")" -> (日) | D26: － | J26: 空手部
A27: 21 | B27: ="("&TEXT(DATE($J$9,$J$10,A27),"aaa")&")" -> (月) | D27: －
A28: 22 | B28: ="("&TEXT(DATE($J$9,$J$10,A28),"aaa")&")" -> (火) | D28: － | J28: 写真部
A29: 23 | B29: ="("&TEXT(DATE($J$9,$J$10,A29),"aaa")&")" -> (水) | D29: － | J29: 化学部
A30: 24 | B30: ="("&TEXT(DATE($J$9,$J$10,A30),"aaa")&")" -> (木) | D30: － | J30: 美術部
A31: 25 | B31: ="("&TEXT(DATE($J$9,$J$10,A31),"aaa")&")" -> (金) | D31: － | J31: 吹奏楽部
A32: 26 | B32: ="("&TEXT(DATE($J$9,$J$10,A32),"aaa")&")" -> (土) | D32: － | J32: 軽音楽部
A33: 27 | B33: ="("&TEXT(DATE($J$9,$J$10,A33),"aaa")&")" -> (日) | D33: － | J33: 茶道部
A34: 28 | B34: ="("&TEXT(DATE($J$9,$J$10,A34),"aaa")&")" -> (月) | D34: － | J34: ダンス部
A35: =IF(J10=2,"",29) -> 29 | B35: =IF(J10=2,"","("&TEXT(DATE($J$9,$J$10,A35),"aaa")&")") -> (火) | D35: － | J35: よさこい部
A36: =IF(J10=2,"",30) -> 30 | B36: =IF(J10=2,"","("&TEXT(DATE($J$9,$J$10,A36),"aaa")&")") -> (水) | D36: － | J36: 自動車部
A37: =IF(OR(J10=1,J10=3,J10=5,J10=7,J10=8,J10=10,J10=12),31,"") | B37: =IF(OR(J10=1,J10=3,J10=5,J10=7,J10=8,J10=10,J10=12),"("&TEXT(DATE($J$9,$J$10,A37),"aaa")&")","") | D37: － | J37: 機械技術部
A38: (注) この計画書は、次のことに留意して作成し、活動月の1週間前までに学生支援係に提出する。 定められた期日までに計画書が提出されない場合は、計画月の活動は認められない。 ①平日の活動は原則として17時まで。②土日祝日の活動時間9時から17時まで。 ③活動場所は他の部と事前に調整する。練習試合もできるだけ事前に相手校と調整する。 ⑤土日祝日の指導担当予定の教員名も明記する。⑥土・日のどちらかは活動をしない日とする。 | J38: 電子計算機部
J40: 発明同好会
J41: フットサル同好会
J42: ジャグリング同好会
C43: C~F列： 15:00~17:00が基本．延長は17:15~18:15の1hが可能．どれだけ入れても良い．（前期，村上は水曜日だけは延長に対応できないので，水曜日の延長が必要な場合は他の先生に相談しよう．）土日も活動が可能．Discordで会議をする場合でも教員が必要ならば一応書いておくと良い． | F43: F列： 「CAD室」or「コンピュータ室」or「CSラボ」がよく使われる．「FPラボ」も使えるようになった． | G43: G列： イベントなどがある場合はそれを． それ以外はグループ名を書いておけば良い． | H43: H列： 基本的には「村上力」を入れておけば良い．村上が対応できない場合は他の教員を入れよう． | J43: 数理同好会
J44: 技術総合研究同好会
A46: 各グループリーダーへ | J46: 応援団
...

Sheet 活動延長願
C1: 学生主事 | E1: 学生課長 | G1: 課長補佐 | I1: 係長 | K1: 係員
K4: =活動計画書!G1 -> 令和7年 | M4: =活動計画書!H1 -> 月 日
E5: 課外活動延長願
A7: 学生主事 殿 | K7: 部活名： | M7: =活動計画書!G3 -> 電子計算機部
K8: 顧問名： | M8: =活動計画書!H5 -> 0
A9: 下記の通り、課外活動時間延長の許可をお願い致します。
A10: A. 大会前の延長（17:15～18:45の1.5時間、年３回まで）
A11: B. 平日の延長（17:15～18:15の１時間）
A13: 1. 大会前延長 | E13: 回目 （上記Aの場合） | N13: 1
A14: 2. 延長の理由 | N14: 2
N15: 3
A16: 理由により（特別な理由がない場合など）延長を認めない場合があります。
A17: 3. 延長を希望する月日と延長時間に対応する顧問名を活動計画書と一致しているか確認して下さい。
B18: 注意（１）各部活動の全顧問の了承を得た上で活動月の１週間前までに学生支援係に提出してください。
B19: 注意（２）17:15以降の指導を行う顧問は時間外労働命令簿を人事給与係に提出下さい。
B20: 注意（３）延長した活動時間は片付けも含む活動終了時刻です。
A22: =活動計画書!J9 -> 2025 | B22: 年 | C22: =活動計画書!J10 -> 4 | D22: 月 | E22: A. 大会前延長(～18:45 まで)の場合は、チェック☑を入れて下さい。
A24: 1 | B24: ="("&TEXT(DATE($A$22,$C$22,A24),"aaa")&")" -> (火) | C24: 2 | D24: ="("&TEXT(DATE($A$22,$C$22,C24),"aaa")&")" -> (水) | E24: 3 | F24: ="("&TEXT(DATE($A$22,$C$22,E24),"aaa")&")" -> (木) | G24: 4 | H24: ="("&TEXT(DATE($A$22,$C$22,G24),"aaa")&")" -> (金) | I24: 5 | J24: ="("&TEXT(DATE($A$22,$C$22,I24),"aaa")&")" -> (土) | K24: 6 | L24: ="("&TEXT(DATE($A$22,$C$22,K24),"aaa")&")" -> (日) | M24: 7 | N24: ="("&TEXT(DATE($A$22,$C$22,M24),"aaa")&")" -> (月)
A25: =活動計画書!H7&"" | C25: =活動計画書!H8&"" | E25: =活動計画書!H9&"" | G25: =活動計画書!H10&"" | I25: =活動計画書!H11&"" | K25: =活動計画書!H12&"" | M25: =活動計画書!H13&""
A26: 8 | B26: ="("&TEXT(DATE($A$22,$C$22,A26),"aaa")&")" -> (火) | C26: 9 | D26: ="("&TEXT(DATE($A$22,$C$22,C26),"aaa")&")" -> (水) | E26: 10 | F26: ="("&TEXT(DATE($A$22,$C$22,E26),"aaa")&")" -> (木) | G26: 11 | H26: ="("&TEXT(DATE($A$22,$C$22,G26),"aaa")&")" -> (金) | I26: 12 | J26: ="("&TEXT(DATE($A$22,$C$22,I26),"aaa")&")" -> (土) | K26: 13 | L26: ="("&TEXT(DATE($A$22,$C$22,K26),"aaa")&")" -> (日) | M26: 14 | N26: ="("&TEXT(DATE($A$22,$C$22,M26),"aaa")&")" -> (月)
A27: =活動計画書!H14&"" | C27: =活動計画書!H15&"" | E27: =活動計画書!H16&"" | G27: =活動計画書!H17&"" | I27: =活動計画書!H18&"" | K27: =活動計画書!H19&"" | M27: =活動計画書!H20&""
A28: 15 | B28: ="("&TEXT(DATE($A$22,$C$22,A28),"aaa")&")" -> (火) | C28: 16 | D28: ="("&TEXT(DATE($A$22,$C$22,C28),"aaa")&")" -> (水) | E28: 17 | F28: ="("&TEXT(DATE($A$22,$C$22,E28),"aaa")&")" -> (木) | G28: 18 | H28: ="("&TEXT(DATE($A$22,$C$22,G28),"aaa")&")" -> (金) | I28: 19 | J28: ="("&TEXT(DATE($A$22,$C$22,I28),"aaa")&")" -> (土) | K28: 20 | L28: ="("&TEXT(DATE($A$22,$C$22,K28),"aaa")&")" -> (日) | M28: 21 | N28: ="("&TEXT(DATE($A$22,$C$22,M28),"aaa")&")" -> (月)
A29: =活動計画書!H21&"" | C29: =活動計画書!H22&"" | E29: =活動計画書!H23&"" | G29: =活動計画書!H24&"" | I29: =活動計画書!H25&"" | K29: =活動計画書!H26&"" | M29: =活動計画書!H27&""
A30: 22 | B30: ="("&TEXT(DATE($A$22,$C$22,A30),"aaa")&")" -> (火) | C30: 23 | D30: ="("&TEXT(DATE($A$22,$C$22,C30),"aaa")&")" -> (水) | E30: 24 | F30: ="("&TEXT(DATE($A$22,$C$22,E30),"aaa")&")" -> (木) | G30: 25 | H30: ="("&TEXT(DATE($A$22,$C$22,G30),"aaa")&")" -> (金) | I30: 26 | J30: ="("&TEXT(DATE($A$22,$C$22,I30),"aaa")&")" -> (土) | K30: 27 | L30: ="("&TEXT(DATE($A$22,$C$22,K30),"aaa")&")" -> (日) | M30: 28 | N30: ="("&TEXT(DATE($A$22,$C$22,M30),"aaa")&")" -> (月)
A31: =活動計画書!H28&"" | C31: =活動計画書!H29&"" | E31: =活動計画書!H30&"" | G31: =活動計画書!H31&"" | I31: =活動計画書!H32&"" | K31: =活動計画書!H33&"" | M31: =活動計画書!H34&""
A32: =IF(C22=2,"",29) -> 29 | B32: =IF(C22=2,"","("&TEXT(DATE($A$22,$C$22,A32),"aaa")&")") -> (火) | C32: =IF(C22=2,"",30) -> 30 | D32: =IF(C22=2,"","("&TEXT(DATE($A$22,$C$22,C32),"aaa")&")") -> (水) | E32: =IF(OR(C22=1,C22=3,C22=5,C22=7,C22=8,C22=10,C22=12),31,"") | F32: =IF(OR(C22=1,C22=3,C22=5,C22=7,C22=8,C22=10,C22=12),"("&TEXT(DATE($A$22,$C$22,E32),"aaa")&")","") | G32: ※ 大会前の延長とは、大会等の2週間以内において、年間3回まで活動の延長を許可するものです。延長時間には片付けの時間を含みます。予選、本選と大会を勝ち進んでいく場合の大会は、全て合わせて1つの大会とみなします。
A33: =活動計画書!H35&"" | C33: =活動計画書!H36&"" | E33: =活動計画書!H37&""
J35: 受理日 : | K35: 令和 年 月 日
J39: サッカー部

Sheet 活動報告書
A1: 令和 7 年 月 日
E3: =活動計画書!E3 -> 令和7年 4月 | G3: 活動報告書 | I3: =活動計画書!G3 -> 電子計算機部
I4: （学生）高橋翔太
I5: （顧問）村上力
A6: 日付 | B6: 曜日 | C6: 活動時間 | F6: 活動場所 | G6: 参加者 | I6: 活動内容 (練習内容・試合結果・特記事項等)
A7: 1 | B7: =活動計画書!B7 -> (火) | C7: =IF(活動計画書!C7="","",活動計画書!C7) -> 0.625 | D7: - | E7: =IF(活動計画書!E7="","",活動計画書!E7) -> 0.70833333 | F7: =活動計画書!F7&"" | H7: 人
A8: 2 | B8: =活動計画書!B8 -> (水) | C8: =IF(活動計画書!C8="","",活動計画書!C8) | D8: - | E8: =IF(活動計画書!E8="","",活動計画書!E8) | F8: =活動計画書!F8&"" | H8: 人
A9: 3 | B9: =活動計画書!B9 -> (木) | C9: =IF(活動計画書!C9="","",活動計画書!C9) | D9: - | E9: =IF(活動計画書!E9="","",活動計画書!E9) | F9: =活動計画書!F9&"" | H9: 人
A10: 4 | B10: =活動計画書!B10 -> (金) | C10: =IF(活動計画書!C10="","",活動計画書!C10) | D10: - | E10: =IF(活動計画書!E10="","",活動計画書!E10) | F10: =活動計画書!F10&"" | H10: 人
A11: 5 | B11: =活動計画書!B11 -> (土) | C11: =IF(活動計画書!C11="","",活動計画書!C11) | D11: - | E11: =IF(活動計画書!E11="","",活動計画書!E11) | F11: =活動計画書!F11&"" | H11: 人
A12: 6 | B12: =活動計画書!B12 -> (日) | C12: =IF(活動計画書!C12="","",活動計画書!C12) | D12: - | E12: =IF(活動計画書!E12="","",活動計画書!E12) | F12: =活動計画書!F12&"" | H12: 人
A13: 7 | B13: =活動計画書!B13 -> (月) | C13: =IF(活動計画書!C13="","",活動計画書!C13) | D13: - | E13: =IF(活動計画書!E13="","",活動計画書!E13) | F13: =活動計画書!F13&"" | H13: 人
A14: 8 | B14: =活動計画書!B14 -> (火) | C14: =IF(活動計画書!C14="","",活動計画書!C14) | D14: - | E14: =IF(活動計画書!E14="","",活動計画書!E14) | F14: =活動計画書!F14&"" | H14: 人
A15: 9 | B15: =活動計画書!B15 -> (水) | C15: =IF(活動計画書!C15="","",活動計画書!C15) | D15: - | E15: =IF(活動計画書!E15="","",活動計画書!E15) | F15: =活動計画書!F15&"" | H15: 人
A16: 10 | B16: =活動計画書!B16 -> (木) | C16: =IF(活動計画書!C16="","",活動計画書!C16) | D16: - | E16: =IF(活動計画書!E16="","",活動計画書!E16) | F16: =活動計画書!F16&"" | H16: 人
A17: 11 | B17: =活動計画書!B17 -> (金) | C17: =IF(活動計画書!C17="","",活動計画書!C17) | D17: - | E17: =IF(活動計画書!E17="","",活動計画書!E17) | F17: =活動計画書!F17&"" | H17: 人
A18: 12 | B18: =活動計画書!B18 -> (土) | C18: =IF(活動計画書!C18="","",活動計画書!C18) | D18: - | E18: =IF(活動計画書!E18="","",活動計画書!E18) | F18: =活動計画書!F18&"" | H18: 人
... A34: 28 | B34: =活動計画書!B34 -> (月) | C34: =IF(活動計画書!C34="","",活動計画書!C34) | D34: - | E34: =IF(活動計画書!E34="","",活動計画書!E34) | F34: =活動計画書!F34&"" | H34: 人
A35: =活動計画書!A35 -> 29 | B35: =活動計画書!B35 -> (火) | C35: =IF(活動計画書!C35="","",活動計画書!C35) | D35: - | E35: =IF(活動計画書!E35="","",活動計画書!E35) | F35: =活動計画書!F35&"" | H35: 人
A36: =活動計画書!A36 -> 30 | B36: =活動計画書!B36 -> (水) | C36: =IF(活動計画書!C36="","",活動計画書!C36) | D36: - | E36: =IF(活動計画書!E36="","",活動計画書!E36) | F36: =活動計画書!F36&"" | H36: 人
A37: =活動計画書!A37 | B37: =活動計画書!B37 | C37: =IF(活動計画書!C37="","",活動計画書!C37) | D37: - | E37: =IF(活動計画書!E37="","",活動計画書!E37) | F37: =活動計画書!F37&"" | H37: 人
A38: 注) この報告書には月の活動内容を記載して、活動月翌月の10日までに学生係に提出する。 特に、次の事柄は明記すること。なお、ボールペン等で記入する。鉛筆・シャープペンシルは不可。 ①試合・大会等の名称と主たる成績。②上位大会への出場決定に関すること。 ③試合の相手校。④怪我等の状況。⑤4月の入部者数、 5月以降では入部・退部者の氏名。 ⑥土日祝日の活動では指導顧問名。⑦その他の必要事項。

Sheet 見本
A1: 43961 | J1: 43915
B3: 令和2年4月 活動報告書 高専運動部 (記入例) | K3: 令和2年4月 活動計画書 高専運動部 (記入例)
A5: (学生) 高専太郎 印 (顧問) 教員太郎 印 | J5: (学生) 高専太郎 印 (顧問) 教員太郎 印
A6: 日付 | B6: 曜日 | C6: 活動時間 | F6: 活動場所 | G6: 参加者 | H6: 活動内容 (練習内容・試合結果・特記事項等) | J6: 日付 | K6: 曜日 | L6: 活動時間 | O6: 活動場所 | P6: 活動予定 | Q6: 担当教員
A7: 1 | B7: (金) | G7: 人 | J7: 1 | K7: (金) | M7: － | Q7: ---
A8: =A7+1 -> 2 | B8: (土) | G8: 人 | J8: =J7+1 -> 2 | K8: (土) | M8: － | Q8: ---
A9: =A8+1 -> 3 | B9: (日) | G9: 人 | J9: =J8+1 -> 3 | K9: (日) | M9: － | Q9: ---
A10: =A9+1 -> 4 | B10: (月) | C10: 0.60416667 | D10: - | E10: 0.70833333 | F10: 本校野球場 | G10: 18人 | H10: 一年生が8人入部した。 | J10: =J9+1 -> 4 | K10: (月) | L10: 0.60416667 | M10: － | N10: 0.70833333 | O10: 本校野球場 | P10: 通常練習 | Q10: ---
A11: =A10+1 -> 5 | B11: (火) | C11: 〃 | D11: - | E11: 〃 | F11: 〃 | G11: 20人 | H11: 5日 3C相沢が軽い捻挫 | J11: =J10+1 -> 5 | K11: (火) | L11: 〃 | M11: － | N11: 〃 | O11: 〃 | P11: 〃 | Q11: ---
A12: =A11+1 -> 6 | B12: (水) | C12: 〃 | D12: - | E12: 〃 | F12: 〃 | G12: 24人 | H12: 月－金は通常練習 | J12: =J11+1 -> 6 | K12: (水) | L12: 〃 | M12: － | N12: 〃 | O12: 〃 | P12: 〃 | Q12: ---
A13: =A12+1 -> 7 | B13: (木) | C13: 〃 | D13: - | E13: 〃 | F13: 〃 | G13: 25人 | H13: 10日（日）は紅白戦。高野連チームが勝利 | J13: =J12+1 -> 7 | K13: (木) | L13: 〃 | M13: － | N13: 〃 | O13: 〃 | P13: 〃 | Q13: ---
A14: =A13+1 -> 8 | B14: (金) | C14: 〃 | D14: - | E14: 〃 | F14: 〃 | G14: 24人 | J14: =J13+1 -> 8 | K14: (金) | L14: 〃 | M14: － | N14: 〃 | O14: 〃 | P14: 〃 | Q14: ---
A15: =A14+1 -> 9 | B15: (土) | D15: - | F15: 休み | G15: 人 | J15: =J14+1 -> 9 | K15: (土) | M15: － | P15: 休み | Q15: ---
A16: =A15+1 -> 10 | B16: (日) | C16: 0.375 | D16: - | E16: 0.70833333 | F16: 釣山球場 | G16: 25人 | H16: 休日指導者 (鈴木 ) | J16: =J15+1 -> 10 | K16: (日) | L16: 0.375 | M16: － | N16: 0.70833333 | O16: 釣山野球場 | P16: 紅白戦 | Q16: 鈴木
A17: =A16+1 -> 11 | B17: (月) | C17: 0.60416667 | D17: - | E17: 0.70833333 | F17: 本校野球場 | G17: 15人 | H17: 月－金は通常練習 | J17: =J16+1 -> 11 | K17: (月) | L17: 0.60416667 | M17: － | N17: 0.70833333 | O17: 本校野球場 | P17: 通常練習 | Q17: ---
A18: =A17+1 -> 12 | B18: (火) | C18: 〃 | D18: - | E18: 〃 | F18: 〃 | G18: 27人 | J18: =J17+1 -> 12 | K18: (火) | L18: 〃 | M18: － | N18: 〃 | O18: 〃 | P18: 〃 | Q18: ---
A19: =A18+1 -> 13 | B19: (水) | C19: 〃 | D19: - | E19: 〃 | F19: 〃 | G19: 30人 | H19: 17日（日）は、練習試合。 | J19: =J18+1 -> 13 | K19: (水) | L19: 〃 | M19: － | N19: 〃 | O19: 〃 | P19: 〃 | Q19: ---
A20: =A19+1 -> 14 | B20: (木) | C20: 0.64583333 | D20: - | E20: 0.70833333 | F20: 〃 | G20: 30人 | H20: 対○○高専戦 6-3 で勝利 | J20: =J19+1 -> 14 | K20: (木) | L20: 0.64583333 | M20: － | N20: 0.70833333 | O20: 〃 | P20: 〃 | Q20: ---
A21: =A20+1 -> 15 | B21: (金) | C21: 0.60416667 | D21: - | E21: 0.70833333 | F21: 〃 | G21: 30人 | J21: =J20+1 -> 15 | K21: (金) | L21: 0.60416667 | M21: － | N21: 0.70833333 | O21: 〃 | P21: 〃 | Q21: ---
A22: =A21+1 -> 16 | B22: (土) | D22: - | F22: 休み | G22: 人 | J22: =J21+1 -> 16 | K22: (土) | M22: － | P22: 休み | Q22: ---
A23: =A22+1 -> 17 | B23: (日) | C23: 0.375 | D23: - | E23: 0.70833333 | F23: 東台球場 | G23: 30人 | H23: 休日指導者 (斎藤 ) | J23: =J22+1 -> 17 | K23: (日) | L23: 0.375 | M23: － | N23: 0.70833333 | O23: 東台野球場 | P23: 練習試合 (○○高専) | Q23: 斎藤
A24: =A23+1 -> 18 | B24: (月) | C24: 0.60416667 | D24: - | E24: 0.70833333 | F24: 本校野球場 | G24: 28人 | H24: 月－金は通常練習 | J24: =J23+1 -> 18 | K24: (月) | L24: 0.60416667 | M24: － | N24: 0.70833333 | O24: 本校野球場 | P24: 通常練習 | Q24: ---
A25: =A24+1 -> 19 | B25: (火) | C25: 〃 | D25: - | E25: 〃 | F25: 〃 | G25: 28人 | H25: 24日 (日) に○○高校と練習試合を行った。 | J25: =J24+1 -> 19 | K25: (火) | L25: 〃 | M25: － | N25: 〃 | O25: 〃 | P25: 〃 | Q25: ---
A26: =A25+1 -> 20 | B26: (水) | C26: 〃 | D26: - | E26: 〃 | F26: 〃 | G26: 28人 | H26: 2-2で引き分け | J26: =J25+1 -> 20 | K26: (水) | L26: 〃 | M26: － | N26: 〃 | O26: 〃 | P26: 〃 | Q26: ---
A27: =A26+1 -> 21 | B27: (木) | C27: 〃 | D27: - | E27: 〃 | F27: 〃 | G27: 27人 | J27: =J26+1 -> 21 | K27: (木) | L27: 〃 | M27: － | N27: 〃 | O27: 〃 | P27: 〃 | Q27: ---
A28: =A27+1 -> 22 | B28: (金) | C28: 〃 | D28: - | E28: 〃 | F28: 〃 | G28: 30人 | J28: =J27+1 -> 22 | K28: (金) | L28: 〃 | M28: － | N28: 〃 | O28: 〃 | P28: 〃 | Q28: ---
A29: =A28+1 -> 23 | B29: (土) | D29: - | F29: 休み | G29: 人 | J29: =J28+1 -> 23 | K29: (土) | M29: － | P29: 休み | Q29: ---
A30: =A29+1 -> 24 | B30: (日) | C30: 0.375 | D30: - | E30: 0.70833333 | F30: ○高グランド | G30: 30人 | H30: 休日指導者 (山田 ) | J30: =J29+1 -> 24 | K30: (日) | L30: 0.375 | M30: － | N30: 0.70833333 | O30: ○○高校グランド | P30: 練習試合 (○○高校) | Q30: 山田
A31: =A30+1 -> 25 | B31: (月) | C31: 0.60416667 | D31: - | E31: 0.70833333 | F31: 本校野球場 | G31: 28人 | H31: 月－金は通常練習 | J31: =J30+1 -> 25 | K31: (月) | L31: 0.60416667 | M31: － | N31: 0.70833333 | O31: 本校野球場 | P31: 通常練習 | Q31: ---
A32: =A31+1 -> 26 | B32: (火) | C32: 〃 | D32: - | E32: 〃 | F32: 〃 | G32: 30人 | J32: =J31+1 -> 26 | K32: (火) | L32: 〃 | M32: － | N32: 〃 | O32: 〃 | P32: 〃 | Q32: ---
A33: =A32+1 -> 27 | B33: (水) | C33: 〃 | D33: - | E33: 〃 | F33: 〃 | G33: 30人 | J33: =J32+1 -> 27 | K33: (水) | L33: 〃 | M33: － | N33: 〃 | O33: 〃 | P33: 〃 | Q33: ---
A34: =A33+1 -> 28 | B34: (木) | C34: 〃 | D34: - | E34: 〃 | F34: 〃 | G34: 28人 | J34: =J33+1 -> 28 | K34: (木) | L34: 〃 | M34: － | N34: 〃 | O34: 〃 | P34: 〃 | Q34: ---
A35: =A34+1 -> 29 | B35: (金) | C35: 0.375 | D35: - | E35: 0.70833333 | F35: 〃 | G35: 30人 | J35: =J34+1 -> 29 | K35: (金) | L35: 0.375 | M35: － | N35: 0.70833333 | O35: 〃 | P35: 〃 | Q35: 佐藤
A36: =A35+1 -> 30 | B36: (土) | D36: - | F36: 休み | G36: 人 | H36: 休日指導者 (佐藤 ) | J36: =J35+1 -> 30 | K36: (土) | M36: － | P36: 休み | Q36: ---
A37: 注) この報告書には月の活動内容を記載して、活動月翌月の10日までに学生係に提出する。 特に、次の事柄は明記すること。なお、ボールペン等で記入する。鉛筆・シャープペンシルは不可。 ①試合・大会等の名称と主たる成績。②上位大会への出場決定に関すること。 ③試合の相手校。④怪我等の状況。⑤4月の入部者数、 5月以降では入部・退部者の氏名。 ⑥土日祝日の活動では指導顧問名。⑦その他の必要事項。 | J37: (注) この計画書は、次のことに留意して作成し、活動月の1週間前までに学生支援係に提出する。 定められた期日までに計画書が提出されない場合は、計画月の活動は認められない。 ①平日の活動は原則として17時まで。②土日祝日の活動時間9時から17時まで。 ③活動場所は他の部と事前に調整する。練習試合もできるだけ事前に相手校と調整する。 ⑤土日祝日の指導担当予定の教員名も明記する。⑥土・日のどちらかは活動をしない日とする。

Sheet 記載要項
A1: 学生会・部・同好会代表者、各位
A3: 学生主事
A5: 課外活動の月間計画書・月間報告書等の作成について
A7: 課外活動の月間計画書と月間報告書は、課外活動が学校の教育計画の下に行われていることを示す上で重要な資料となるものです。下記の事項に留意して作成し、決められた期日までに学生支援係に提出して下さい。
A9: [1] 課外活動の月間活動計画書の作成要領
A10: (1) 翌月の活動計画を期日ごとに記載し、活動月の1週間前までに学生支援係に提出する。
A11: この計画書が無いと、事故の際に災害共済給付が支給されない場合がある。
A12: 決められた期日までに提出されない場合は、活動予定月の活動は認められない。
A13: (2) 活動時間、活動場所、そして活動内容について記載する。
A14: (3) 平日の活動時間は、原則として17:00までである。
A15: (4) 土日祝日の課外活動は、9:00から17:00までとし、土・日のどちらかは活動をしない日とする。
A16: ・3連休以上のときは、原則として1日以上休みの日を設けて計画する。
... A61: 何らかの事故が発生したとき緊急連絡先として必要なので、4月中旬頃までに作成して学生支援係まで提出してください。提出された情報については、学校として責任をもって管理します。
